îº§ Environment updated. Reloading shell...
2025-05-05 14:33:20 INFO     discord.client logging in using static token
2025-05-05 14:33:20 INFO     discord.gateway Shard ID None has connected to Gateway (Session ID: 50fa77b371bcbc2f155291d7686d9ef2).
[âœ…] Logged in as FC8 Moderation#1065
[ðŸ”§] Registered 4 global slash command(s).
2025-05-05 14:33:28 ERROR    discord.app_commands.tree Ignoring exception in command 'kick'
Traceback (most recent call last):
  File "/home/runner/workspace/main.py", line 103, in kick
    await interaction.response.send_message(embed=embed)
  File "/home/runner/workspace/.pythonlibs/lib/python3.11/site-packages/discord/interactions.py", line 976, in send_message
    raise InteractionResponded(self._parent)
discord.errors.InteractionResponded: This interaction has already been responded to before

During handling of the above exception, another exception occurred:

Traceback (most recent call last):
  File "/home/runner/workspace/.pythonlibs/lib/python3.11/site-packages/discord/app_commands/commands.py", line 858, in _do_call
    return await self._callback(interaction, **params)  # type: ignore
           ^^^^^^^^^^^^^^^^^^^^^^^^^^^^^^^^^^^^^^^^^^^
  File "/home/runner/workspace/main.py", line 106, in kick
    await interaction.response.send_message(
  File "/home/runner/workspace/.pythonlibs/lib/python3.11/site-packages/discord/interactions.py", line 976, in send_message
    raise InteractionResponded(self._parent)
discord.errors.InteractionResponded: This interaction has already been responded to before

The above exception was the direct cause of the following exception:

Traceback (most recent call last):
  File "/home/runner/workspace/.pythonlibs/lib/python3.11/site-packages/discord/app_commands/tree.py", line 1310, in _call
    await command._invoke_with_namespace(interaction, namespace)
  File "/home/runner/workspace/.pythonlibs/lib/python3.11/site-packages/discord/app_commands/commands.py", line 883, in _invoke_with_namespace
    return await self._do_call(interaction, transformed_values)
           ^^^^^^^^^^^^^^^^^^^^^^^^^^^^^^^^^^^^^^^^^^^^^^^^^^^^
  File "/home/runner/workspace/.pythonlibs/lib/python3.11/site-packages/discord/app_commands/commands.py", line 876, in _do_call
    raise CommandInvokeError(self, e) from e
discord.app_commands.errors.CommandInvokeError: Command 'kick' raised an exception: InteractionResponded: This interaction has already been responded to before
^C